Traceback (most recent call last):
  File "C:\Users\sangouda\AppData\Local\Programs\Python\Python312\Lib\site-packages\jupyter_cache\executors\utils.py", line 58, in single_nb_execution
    executenb(
  File "C:\Users\sangouda\AppData\Local\Programs\Python\Python312\Lib\site-packages\nbclient\client.py", line 1204, in execute
    return NotebookClient(nb=nb, resources=resources, km=km, **kwargs).execute()
           ^^^^^^^^^^^^^^^^^^^^^^^^^^^^^^^^^^^^^^^^^^^^^^^^^^^^^^^^^^^^^^^^^^^^^
  File "C:\Users\sangouda\AppData\Local\Programs\Python\Python312\Lib\site-packages\nbclient\util.py", line 84, in wrapped
    return just_run(coro(*args, **kwargs))
           ^^^^^^^^^^^^^^^^^^^^^^^^^^^^^^^
  File "C:\Users\sangouda\AppData\Local\Programs\Python\Python312\Lib\site-packages\nbclient\util.py", line 62, in just_run
    return loop.run_until_complete(coro)
           ^^^^^^^^^^^^^^^^^^^^^^^^^^^^^
  File "C:\Users\sangouda\AppData\Local\Programs\Python\Python312\Lib\asyncio\base_events.py", line 664, in run_until_complete
    return future.result()
           ^^^^^^^^^^^^^^^
  File "C:\Users\sangouda\AppData\Local\Programs\Python\Python312\Lib\site-packages\nbclient\client.py", line 663, in async_execute
    await self.async_execute_cell(
  File "C:\Users\sangouda\AppData\Local\Programs\Python\Python312\Lib\site-packages\nbclient\client.py", line 965, in async_execute_cell
    await self._check_raise_for_error(cell, cell_index, exec_reply)
  File "C:\Users\sangouda\AppData\Local\Programs\Python\Python312\Lib\site-packages\nbclient\client.py", line 862, in _check_raise_for_error
    raise CellExecutionError.from_cell_and_msg(cell, exec_reply_content)
nbclient.exceptions.CellExecutionError: An error occurred while executing the following cell:
------------------
arr = np.array([1, 2, 1, 1, 3, 4, 3, 1, 1, 2, 1, 1, 2])
print("Inputs\n", arr)
n = int(input(" n = ")) -1
i=int(input(" i = "))
a = np.where(arr==i)[0]
print(" Output\n",a[n])
------------------

[31m---------------------------------------------------------------------------[39m
[31mStdinNotImplementedError[39m                  Traceback (most recent call last)
[36mCell[39m[36m [39m[32mIn[14][39m[32m, line 3[39m
[32m      1[39m arr = np.array([[32m1[39m, [32m2[39m, [32m1[39m, [32m1[39m, [32m3[39m, [32m4[39m, [32m3[39m, [32m1[39m, [32m1[39m, [32m2[39m, [32m1[39m, [32m1[39m, [32m2[39m])
[32m      2[39m [38;5;28mprint[39m([33m"[39m[33mInputs[39m[38;5;130;01m\n[39;00m[33m"[39m, arr)
[32m----> [39m[32m3[39m n = [38;5;28mint[39m([38;5;28;43minput[39;49m[43m([49m[33;43m"[39;49m[33;43m n = [39;49m[33;43m"[39;49m[43m)[49m) -[32m1[39m
[32m      4[39m i=[38;5;28mint[39m([38;5;28minput[39m([33m"[39m[33m i = [39m[33m"[39m))
[32m      5[39m a = np.where(arr==i)[[32m0[39m]

[36mFile [39m[32m~\AppData\Local\Programs\Python\Python312\Lib\site-packages\ipykernel\kernelbase.py:1281[39m, in [36mKernel.raw_input[39m[34m(self, prompt)[39m
[32m   1279[39m [38;5;28;01mif[39;00m [38;5;129;01mnot[39;00m [38;5;28mself[39m._allow_stdin:
[32m   1280[39m     msg = [33m"[39m[33mraw_input was called, but this frontend does not support input requests.[39m[33m"[39m
[32m-> [39m[32m1281[39m     [38;5;28;01mraise[39;00m StdinNotImplementedError(msg)
[32m   1282[39m [38;5;28;01mreturn[39;00m [38;5;28mself[39m._input_request(
[32m   1283[39m     [38;5;28mstr[39m(prompt),
[32m   1284[39m     [38;5;28mself[39m._parent_ident[[33m"[39m[33mshell[39m[33m"[39m],
[32m   1285[39m     [38;5;28mself[39m.get_parent([33m"[39m[33mshell[39m[33m"[39m),
[32m   1286[39m     password=[38;5;28;01mFalse[39;00m,
[32m   1287[39m )

[31mStdinNotImplementedError[39m: raw_input was called, but this frontend does not support input requests.
StdinNotImplementedError: raw_input was called, but this frontend does not support input requests.

